<sdf version='1.7'>
  <model name='panda'>
    <joint name='robot_to_world' type='fixed'>
      <pose>0 0 0 0 -0 0</pose>
      <parent>world</parent>
      <child>panda_link0</child>
    </joint>
    <link name='panda_link0'>
      <pose>0 0 0 0 -0 0</pose>
      <inertial>
        <pose>0 0 0 0 -0 0</pose>
        <mass>3.06357</mass>
        <inertia>
          <ixx>0.3</ixx>
          <ixy>0</ixy>
          <ixz>0</ixz>
          <iyy>0.3</iyy>
          <iyz>0</iyz>
          <izz>0.3</izz>
        </inertia>
      </inertial>
      <collision name='panda_link0_collision'>
        <pose>0 0 0 0 -0 0</pose>
        <geometry>
          <mesh>
            <scale>1 1 1</scale>
            <uri>model://panda_arm/meshes/collision/link0.stl</uri>
          </mesh>
        </geometry>
        <surface>
          <contact>
            <ode/>
          </contact>
          <friction>
            <ode>
              <mu>0.2</mu>
              <mu2>0.2</mu2>
            </ode>
          </friction>
        </surface>
      </collision>
      <visual name='panda_link0_visual'>
        <pose>0 0 0 0 -0 0</pose>
        <geometry>
          <mesh>
            <scale>1 1 1</scale>
            <uri>model://panda_arm/meshes/visual/link0.dae</uri>
          </mesh>
        </geometry>
        <material>
          <script>
            <name>Gazebo/Grey</name>
            <uri>file://media/materials/scripts/gazebo.material</uri>
          </script>
        </material>
      </visual>
      <gravity>1</gravity>
      <velocity_decay/>
    </link>
    <joint name='panda_joint1' type='revolute'>
      <pose>0 0 0.333 0 -0 0</pose>
      <parent>panda_link0</parent>
      <child>panda_link1</child>
      <axis>
        <xyz>0 0 1</xyz>
        <limit>
          <lower>-2.8973</lower>
          <upper>2.8973</upper>
          <effort>87</effort>
          <velocity>2.175</velocity>
        </limit>
        <dynamics>
          <damping>1</damping>
          <friction>0</friction>
          <spring_reference>0</spring_reference>
          <spring_stiffness>0</spring_stiffness>
        </dynamics>
      </axis>
    </joint>
    <link name='panda_link1'>
      <pose>0 0 0 0 -0 0</pose>
      <inertial>
        <pose>0 0 0 0 -0 0</pose>
        <mass>2.34471</mass>
        <inertia>
          <ixx>0.3</ixx>
          <ixy>0</ixy>
          <ixz>0</ixz>
          <iyy>0.3</iyy>
          <iyz>0</iyz>
          <izz>0.3</izz>
        </inertia>
      </inertial>
      <collision name='panda_link1_collision'>
        <pose>0 0 0 0 -0 0</pose>
        <geometry>
          <mesh>
            <scale>1 1 1</scale>
            <uri>model://panda_arm/meshes/collision/link1.stl</uri>
          </mesh>
        </geometry>
        <surface>
          <contact>
            <ode/>
          </contact>
          <friction>
            <ode>
              <mu>0.2</mu>
              <mu2>0.2</mu2>
            </ode>
          </friction>
        </surface>
      </collision>
      <visual name='panda_link1_visual'>
        <pose>0 0 0 0 -0 0</pose>
        <geometry>
          <mesh>
            <scale>1 1 1</scale>
            <uri>model://panda_arm/meshes/visual/link1.dae</uri>
          </mesh>
        </geometry>
        <material>
          <script>
            <name>Gazebo/White</name>
            <uri>file://media/materials/scripts/gazebo.material</uri>
          </script>
        </material>
      </visual>
      <gravity>1</gravity>
      <velocity_decay/>
    </link>
    <joint name='panda_joint2' type='revolute'>
      <pose>0 0 0 -1.5708 0 0</pose>
      <parent>panda_link1</parent>
      <child>panda_link2</child>
      <axis>
        <xyz>0 0 1</xyz>
        <limit>
          <lower>-1.7628</lower>
          <upper>1.7628</upper>
          <effort>87</effort>
          <velocity>2.175</velocity>
        </limit>
        <dynamics>
          <damping>1</damping>
          <friction>0</friction>
          <spring_reference>0</spring_reference>
          <spring_stiffness>0</spring_stiffness>
        </dynamics>
      </axis>
    </joint>
    <link name='panda_link2'>
      <pose>0 0 0 0 -0 0</pose>
      <inertial>
        <pose>0 0 0 0 -0 0</pose>
        <mass>2.36414</mass>
        <inertia>
          <ixx>0.3</ixx>
          <ixy>0</ixy>
          <ixz>0</ixz>
          <iyy>0.3</iyy>
          <iyz>0</iyz>
          <izz>0.3</izz>
        </inertia>
      </inertial>
      <collision name='panda_link2_collision'>
        <pose>0 0 0 0 -0 0</pose>
        <geometry>
          <mesh>
            <scale>1 1 1</scale>
            <uri>model://panda_arm/meshes/collision/link2.stl</uri>
          </mesh>
        </geometry>
        <surface>
          <contact>
            <ode/>
          </contact>
          <friction>
            <ode>
              <mu>0.2</mu>
              <mu2>0.2</mu2>
            </ode>
          </friction>
        </surface>
      </collision>
      <visual name='panda_link2_visual'>
        <pose>0 0 0 0 -0 0</pose>
        <geometry>
          <mesh>
            <scale>1 1 1</scale>
            <uri>model://panda_arm/meshes/visual/link2.dae</uri>
          </mesh>
        </geometry>
        <material>
          <script>
            <name>Gazebo/White</name>
            <uri>file://media/materials/scripts/gazebo.material</uri>
          </script>
        </material>
      </visual>
      <gravity>1</gravity>
      <velocity_decay/>
    </link>
    <joint name='panda_joint3' type='revolute'>
      <pose>0 -0.316 0 1.5708 -0 0</pose>
      <parent>panda_link2</parent>
      <child>panda_link3</child>
      <axis>
        <xyz>0 0 1</xyz>
        <limit>
          <lower>-2.8973</lower>
          <upper>2.8973</upper>
          <effort>87</effort>
          <velocity>2.175</velocity>
        </limit>
        <dynamics>
          <damping>1</damping>
          <friction>0</friction>
          <spring_reference>0</spring_reference>
          <spring_stiffness>0</spring_stiffness>
        </dynamics>
      </axis>
    </joint>
    <link name='panda_link3'>
      <pose>0 0 0 0 -0 0</pose>
      <inertial>
        <pose>0 0 0 0 -0 0</pose>
        <mass>2.3805</mass>
        <inertia>
          <ixx>0.3</ixx>
          <ixy>0</ixy>
          <ixz>0</ixz>
          <iyy>0.3</iyy>
          <iyz>0</iyz>
          <izz>0.3</izz>
        </inertia>
      </inertial>
      <collision name='panda_link3_collision'>
        <pose>0 0 0 0 -0 0</pose>
        <geometry>
          <mesh>
            <scale>1 1 1</scale>
            <uri>model://panda_arm/meshes/collision/link3.stl</uri>
          </mesh>
        </geometry>
        <surface>
          <contact>
            <ode/>
          </contact>
          <friction>
            <ode>
              <mu>0.2</mu>
              <mu2>0.2</mu2>
            </ode>
          </friction>
        </surface>
      </collision>
      <visual name='panda_link3_visual'>
        <pose>0 0 0 0 -0 0</pose>
        <geometry>
          <mesh>
            <scale>1 1 1</scale>
            <uri>model://panda_arm/meshes/visual/link3.dae</uri>
          </mesh>
        </geometry>
        <material>
          <script>
            <name>Gazebo/White</name>
            <uri>file://media/materials/scripts/gazebo.material</uri>
          </script>
        </material>
      </visual>
      <gravity>1</gravity>
      <velocity_decay/>
    </link>
    <joint name='panda_joint4' type='revolute'>
      <pose>0.0825 0 0 1.5708 -0 0</pose>
      <parent>panda_link3</parent>
      <child>panda_link4</child>
      <axis>
        <xyz>0 0 1</xyz>
        <limit>
          <lower>-3.0718</lower>
          <upper>-0.0698</upper>
          <effort>87</effort>
          <velocity>2.175</velocity>
        </limit>
        <dynamics>
          <damping>1</damping>
          <friction>0</friction>
          <spring_reference>0</spring_reference>
          <spring_stiffness>0</spring_stiffness>
        </dynamics>
      </axis>
    </joint>
    <link name='panda_link4'>
      <pose>0 0 0 0 -0 0</pose>
      <inertial>
        <pose>0 0 0 0 -0 0</pose>
        <mass>2.42754</mass>
        <inertia>
          <ixx>0.3</ixx>
          <ixy>0</ixy>
          <ixz>0</ixz>
          <iyy>0.3</iyy>
          <iyz>0</iyz>
          <izz>0.3</izz>
        </inertia>
      </inertial>
      <collision name='panda_link4_collision'>
        <pose>0 0 0 0 -0 0</pose>
        <geometry>
          <mesh>
            <scale>1 1 1</scale>
            <uri>model://panda_arm/meshes/collision/link4.stl</uri>
          </mesh>
        </geometry>
        <surface>
          <contact>
            <ode/>
          </contact>
          <friction>
            <ode>
              <mu>0.2</mu>
              <mu2>0.2</mu2>
            </ode>
          </friction>
        </surface>
      </collision>
      <visual name='panda_link4_visual'>
        <pose>0 0 0 0 -0 0</pose>
        <geometry>
          <mesh>
            <scale>1 1 1</scale>
            <uri>model://panda_arm/meshes/visual/link4.dae</uri>
          </mesh>
        </geometry>
        <material>
          <script>
            <name>Gazebo/White</name>
            <uri>file://media/materials/scripts/gazebo.material</uri>
          </script>
        </material>
      </visual>
      <gravity>1</gravity>
      <velocity_decay/>
    </link>
    <joint name='panda_joint5' type='revolute'>
      <pose>-0.0825 0.384 0 -1.5708 0 0</pose>
      <parent>panda_link4</parent>
      <child>panda_link5</child>
      <axis>
        <xyz>0 0 1</xyz>
        <limit>
          <lower>-2.8973</lower>
          <upper>2.8973</upper>
          <effort>12</effort>
          <velocity>2.61</velocity>
        </limit>
        <dynamics>
          <damping>1</damping>
          <friction>0</friction>
          <spring_reference>0</spring_reference>
          <spring_stiffness>0</spring_stiffness>
        </dynamics>
      </axis>
    </joint>
    <link name='panda_link5'>
      <pose>0 0 0 0 -0 0</pose>
      <inertial>
        <pose>0 0 0 0 -0 0</pose>
        <mass>3.49611</mass>
        <inertia>
          <ixx>0.3</ixx>
          <ixy>0</ixy>
          <ixz>0</ixz>
          <iyy>0.3</iyy>
          <iyz>0</iyz>
          <izz>0.3</izz>
        </inertia>
      </inertial>
      <collision name='panda_link5_collision'>
        <pose>0 0 0 0 -0 0</pose>
        <geometry>
          <mesh>
            <scale>1 1 1</scale>
            <uri>model://panda_arm/meshes/collision/link5.stl</uri>
          </mesh>
        </geometry>
        <surface>
          <contact>
            <ode/>
          </contact>
          <friction>
            <ode>
              <mu>0.2</mu>
              <mu2>0.2</mu2>
            </ode>
          </friction>
        </surface>
      </collision>
      <visual name='panda_link5_visual'>
        <pose>0 0 0 0 -0 0</pose>
        <geometry>
          <mesh>
            <scale>1 1 1</scale>
            <uri>model://panda_arm/meshes/visual/link5.dae</uri>
          </mesh>
        </geometry>
        <material>
          <script>
            <name>Gazebo/White</name>
            <uri>file://media/materials/scripts/gazebo.material</uri>
          </script>
        </material>
      </visual>
      <gravity>1</gravity>
      <velocity_decay/>
    </link>
    <joint name='panda_joint6' type='revolute'>
      <pose>0 0 0 1.5708 -0 0</pose>
      <parent>panda_link5</parent>
      <child>panda_link6</child>
      <axis>
        <xyz>0 0 1</xyz>
        <limit>
          <lower>-0.0175</lower>
          <upper>3.7525</upper>
          <effort>12</effort>
          <velocity>2.61</velocity>
        </limit>
        <dynamics>
          <damping>1</damping>
          <friction>0</friction>
          <spring_reference>0</spring_reference>
          <spring_stiffness>0</spring_stiffness>
        </dynamics>
      </axis>
    </joint>
    <link name='panda_link6'>
      <pose>0 0 0 0 -0 0</pose>
      <inertial>
        <pose>0 0 0 0 -0 0</pose>
        <mass>1.46736</mass>
        <inertia>
          <ixx>0.3</ixx>
          <ixy>0</ixy>
          <ixz>0</ixz>
          <iyy>0.3</iyy>
          <iyz>0</iyz>
          <izz>0.3</izz>
        </inertia>
      </inertial>
      <collision name='panda_link6_collision'>
        <pose>0 0 0 0 -0 0</pose>
        <geometry>
          <mesh>
            <scale>1 1 1</scale>
            <uri>model://panda_arm/meshes/collision/link6.stl</uri>
          </mesh>
        </geometry>
        <surface>
          <contact>
            <ode/>
          </contact>
          <friction>
            <ode>
              <mu>0.2</mu>
              <mu2>0.2</mu2>
            </ode>
          </friction>
        </surface>
      </collision>
      <visual name='panda_link6_visual'>
        <pose>0 0 0 0 -0 0</pose>
        <geometry>
          <mesh>
            <scale>1 1 1</scale>
            <uri>model://panda_arm/meshes/visual/link6.dae</uri>
          </mesh>
        </geometry>
        <material>
          <script>
            <name>Gazebo/White</name>
            <uri>file://media/materials/scripts/gazebo.material</uri>
          </script>
        </material>
      </visual>
      <gravity>1</gravity>
      <velocity_decay/>
    </link>
    <joint name='panda_joint7' type='revolute'>
      <pose>0.088 0 0 1.5708 -0 0</pose>
      <parent>panda_link6</parent>
      <child>panda_link7</child>
      <axis>
        <xyz>0 0 1</xyz>
        <limit>
          <lower>-2.8973</lower>
          <upper>2.8973</upper>
          <effort>12</effort>
          <velocity>2.61</velocity>
        </limit>
        <dynamics>
          <damping>1</damping>
          <friction>0</friction>
          <spring_reference>0</spring_reference>
          <spring_stiffness>0</spring_stiffness>
        </dynamics>
      </axis>
    </joint>
    <link name='panda_link7'>
      <pose>0 0 0 0 -0 0</pose>
      <inertial>
        <pose>0 0 0 0 -0 0</pose>
        <mass>0.45606</mass>
        <inertia>
          <ixx>0.3</ixx>
          <ixy>0</ixy>
          <ixz>0</ixz>
          <iyy>0.3</iyy>
          <iyz>0</iyz>
          <izz>0.3</izz>
        </inertia>
      </inertial>
      <collision name='panda_link7_collision'>
        <pose>0 0 0 0 -0 0</pose>
        <geometry>
          <mesh>
            <scale>1 1 1</scale>
            <uri>model://panda_arm/meshes/collision/link7.stl</uri>
          </mesh>
        </geometry>
        <surface>
          <contact>
            <ode/>
          </contact>
          <friction>
            <ode>
              <mu>0.2</mu>
              <mu2>0.2</mu2>
            </ode>
          </friction>
        </surface>
      </collision>
      <visual name='panda_link7_visual'>
        <pose>0 0 0 0 -0 0</pose>
        <geometry>
          <mesh>
            <scale>1 1 1</scale>
            <uri>model://panda_arm/meshes/visual/link7.dae</uri>
          </mesh>
        </geometry>
        <material>
          <script>
            <name>Gazebo/Grey</name>
            <uri>file://media/materials/scripts/gazebo.material</uri>
          </script>
        </material>
      </visual>
      <velocity_decay/>
      <gravity>1</gravity>
      <velocity_decay/>
    </link>
    <static>0</static>
    <plugin name='gazebo_ros_control' filename='libgazebo_ros_control.so'/>
  </model>
</sdf>
